<?xml version='1.0' encoding='utf-8'?>
<mujoco model="mybot_v3">
    <compiler angle="radian" meshdir="../meshes/" autolimits="true" />
    <size njmax="500" nconmax="100" />
    <option gravity="0 0 -9.806" iterations="50" solver="Newton" timestep="0.002" />

    <default>
        <default class="dog_v2">
            <geom contype="1" conaffinity="1" friction="0.6 0.3 0.3" rgba="0.5 0.6 0.7 1" margin="0.001" group="0" />
            <joint armature="0.01" damping="2" frictionloss="0.2" />
            <motor ctrlrange="-33.5 33.5" ctrllimited="true" />
            
            <default class="abduction">
                <joint damping="1" />
            </default>
            <default class="thigh">
                <joint damping="2" />
            </default>
            <default class="calf">
                <joint damping="2" armature="0.0544" />
                <motor gear="2.3333" />
            </default>
        </default>

        <light castshadow="false" diffuse="1 1 1" />
        <camera fovy="60" />
    </default>

    <asset>
        <mesh name="body" file="body.STL" />
        <mesh name="FL_hip" file="FL_hip.STL" />
        <mesh name="FL_thigh" file="FL_thigh.STL" />
        <mesh name="FL_calf" file="FL_calf.STL" />
        <mesh name="FL_foot" file="FL_foot.STL" />
        <mesh name="FR_hip" file="FR_hip.STL" />
        <mesh name="FR_thigh" file="FR_thigh.STL" />
        <mesh name="FR_calf" file="FR_calf.STL" />
        <mesh name="FR_foot" file="FR_foot.STL" />
        <mesh name="RL_hip" file="RL_hip.STL" />
        <mesh name="RL_thigh" file="RL_thigh.STL" />
        <mesh name="RL_calf" file="RL_calf.STL" />
        <mesh name="RL_foot" file="RL_foot.STL" />
        <mesh name="RR_hip" file="RR_hip.STL" />
        <mesh name="RR_thigh" file="RR_thigh.STL" />
        <mesh name="RR_calf" file="RR_calf.STL" />
        <mesh name="RR_foot" file="RR_foot.STL" />

        <texture type="skybox" builtin="gradient" rgb1="1.0 1.0 1.0" rgb2="1.0 1.0 1.0" width="512" height="512" />
        <texture name="plane" type="2d" builtin="flat" rgb1="1 1 1" rgb2="1 1 1" width="512" height="512" mark="cross" markrgb="0 0 0" />
        <material name="plane" reflectance="0.0" texture="plane" texrepeat="3 3" texuniform="true" />
    </asset>

    <visual>
        <rgba com="0.502 1.0 0 0.5" contactforce="0.98 0.4 0.4 0.7" contactpoint="1.0 1.0 0.6 0.4" />
        <scale com="0.2" forcewidth="0.035" contactwidth="0.10" contactheight="0.04" />
    </visual>

    <worldbody>
        <light directional="true" diffuse=".8 .8 .8" pos="0 0 10" dir="0 0 -10" />
        <camera name="track" mode="trackcom" pos="0 -1.3 1.6" xyaxes="1 0 0 0 0.707 0.707" />
        <geom name="floor" type="plane" conaffinity="1" condim="3" contype="1" rgba="0.5 0.9 0.9 0.1" material="plane" pos="0 0 0" size="0 0 1" />

        <body name="body" pos="0 0 0.35" childclass="dog_v2">
            <inertial pos="0.00000000 0.00000000 0.00000000" mass="3.87237343" fullinertia="0.02571059 0.06723291 0.07677825 0.00000003 0.00005548 0.00000039" />
            <joint type="free" />
            <geom type="mesh" contype="0" conaffinity="0" group="1" rgba="0.847 0.847 0.847 1" mesh="body" />
            <geom size="0.15 0.1 0.08" pos="-0.0 0 -0.0" type="box" rgba="0.913 0.913 0.847 0" />
            <site name="imu" pos="0 0 0" />

            <body name="FL_hip" pos="0.15078 0.062035 0.0028793">
                <inertial pos="0.06912954 0.00308032 -0.00003864" mass="0.88715151" fullinertia="0.00069961 0.00185101 0.00156540 -0.00005524 0.00000161 -0.00000029" />
                <joint class="abduction" name="FL_hip_joint" pos="0 0 0" axis="1 0 0" range="-0.8 0.8" />
                <geom type="mesh" contype="0" conaffinity="0" group="1" rgba="1 1 1 1" mesh="FL_hip" />
                <geom size="0.04 0.03" euler="1.5707963 0 0" type="cylinder" rgba="0.913 0.913 0.847 0" />

                <body name="FL_thigh" pos="0.0889996956253644 0.0289500000000045 0">
                    <inertial pos="-0.02888348 0.05108903 -0.02037010" mass="1.44059854" fullinertia="0.00402900 0.00718366 0.00544974 0.00102313 -0.00259373 0.00071731" />
                    <joint class="thigh" name="FL_thigh_joint" pos="0 0 0" axis="0 1 0" range="-1.04 4.18" />
                    <geom type="mesh" contype="0" conaffinity="0" group="1" rgba="1 1 1 1" mesh="FL_thigh" />
                    <geom size="0.02 0.02 0.1" pos="0 0.08 -0.1" type="box" rgba="0.913 0.913 0.847 0" />
                    
                    <body name="FL_calf" pos="0 0.075299999999995 -0.220000271728273">
                        <inertial pos="0.05156601 0.00018731 -0.04379412" mass="0.23708419" fullinertia="0.00070235 0.00207462 0.00144807 -0.00000272 0.00091520 0.00000190" />
                        <joint class="calf" name="FL_calf_joint" pos="0 0 0" axis="0 1 0" range="-2.69 -0.91" />
                        <geom type="mesh" contype="0" conaffinity="0" group="1" rgba="0.847 0.847 0.847 1" mesh="FL_calf" />
                        <geom size="0.01 0.01 0.1" pos="0 0 -0.1" type="box" rgba="0 0 0 0" />
                        
                        <body name="FL_foot" pos="0 0.000400000000007244 -0.226044482407549">
                            <inertial pos="0.00000000 0.00000000 0.00000000" mass="0.03900000" fullinertia="0.00000624 0.00000624 0.00000624 0.00000000 0.00000000 0.00000000" />
                            <geom type="mesh" contype="0" conaffinity="0" group="1" rgba="0.298 0.298 0.298 1" mesh="FL_foot" />
                            <geom size="0.02" type="sphere" rgba="0 0 0 1" />
                        </body>
                    </body>
                </body>
            </body>

            <body name="FR_hip" pos="0.15078 -0.061965 0.0028793">
                <inertial pos="0.06924676 -0.00308032 -0.00003847" mass="0.88715151" fullinertia="0.00069961 0.00185513 0.00156952 0.00005408 -0.00000026 0.00000029" />
                <joint class="abduction" name="FR_hip_joint" pos="0 0 0" axis="1 0 0" range="-0.8 0.8" />
                <geom type="mesh" contype="0" conaffinity="0" group="1" rgba="1 1 1 1" mesh="FR_hip" />
                <geom size="0.04 0.03" euler="1.5707963 0 0" type="cylinder" rgba="0.913 0.913 0.847 0" />

                <body name="FR_thigh" pos="0.0889996956253649 -0.0289500000000027 0">
                    <inertial pos="-0.02893003 -0.05108904 -0.02031487" mass="1.44059854" fullinertia="0.00403040 0.00718302 0.00544770 -0.00102127 -0.00259435 -0.00071952" />
                    <joint class="thigh" name="FR_thigh_joint" pos="0 0 0" axis="0 1 0" range="-1.04 4.18" />
                    <geom type="mesh" contype="0" conaffinity="0" group="1" rgba="1 1 1 1" mesh="FR_thigh" />
                    <geom size="0.02 0.02 0.1" pos="0 -0.08 -0.1" type="box" rgba="0.913 0.913 0.847 0" />
                    
                    <body name="FR_calf" pos="0 -0.0752999999999995 -0.220000271728275">
                        <inertial pos="0.05155465 -0.00019685 -0.04378873" mass="0.23708419" fullinertia="0.00070228 0.00207435 0.00144787 0.00000301 0.00091508 -0.00000213" />
                        <joint class="calf" name="FR_calf_joint" pos="0 0 0" axis="0 1 0" range="-2.69 -0.91" />
                        <geom type="mesh" contype="0" conaffinity="0" group="1" rgba="0.847 0.847 0.847 1" mesh="FR_calf" />
                        <geom size="0.01 0.01 0.1" pos="0 0 -0.1" type="box" rgba="0 0 0 0" />
                        
                        <body name="FR_foot" pos="0 -0.000399999999994072 -0.226044482407548">
                            <inertial pos="0.00000000 0.00000000 0.00000000" mass="0.03900000" fullinertia="0.00000624 0.00000624 0.00000624 0.00000000 0.00000000 0.00000000" />
                            <geom type="mesh" contype="0" conaffinity="0" group="1" rgba="0.298 0.298 0.298 1" mesh="FR_foot" />
                            <geom size="0.02" type="sphere" rgba="0 0 0 1" />
                        </body>
                    </body>
                </body>
            </body>

            <body name="RL_hip" pos="-0.15042 0.062035 0.0028793">
                <inertial pos="-0.06912961 0.00308032 0.00003847" mass="0.88715151" fullinertia="0.00069961 0.00185101 0.00156540 0.00005524 0.00000161 0.00000029" />
                <joint class="abduction" name="RL_hip_joint" pos="0 0 0" axis="1 0 0" range="-0.8 0.8" />
                <geom type="mesh" contype="0" conaffinity="0" group="1" rgba="1 1 1 1" mesh="RL_hip" />
                <geom size="0.04 0.03" euler="1.5707963 0 0" type="cylinder" rgba="0.913 0.913 0.847 0" />

                <body name="RL_thigh" pos="-0.0889996956253643 0.0289499874999981 0">
                    <inertial pos="-0.02981118 0.05142476 -0.01901311" mass="1.45185979" fullinertia="0.00384286 0.00725341 0.00575250 0.00104947 -0.00254354 0.00066590" />
                    <joint class="thigh" name="RL_thigh_joint" pos="0 0 0" axis="0 1 0" range="-1.04 4.18" />
                    <geom type="mesh" contype="0" conaffinity="0" group="1" rgba="1 1 1 1" mesh="RL_thigh" />
                    <geom size="0.02 0.02 0.1" pos="0 0.08 -0.1" type="box" rgba="0.913 0.913 0.847 0" />
                    
                    <body name="RL_calf" pos="0 0.0752999999999953 -0.220000271728273">
                        <inertial pos="0.05423569 0.00000883 -0.03966053" mass="0.23880158" fullinertia="0.00057526 0.00208160 0.00158150 0.00000037 0.00085435 -0.00000027" />
                        <joint class="calf" name="RL_calf_joint" pos="0 0 0" axis="0 1 0" range="-2.69 -0.91" />
                        <geom type="mesh" contype="0" conaffinity="0" group="1" rgba="0.847 0.847 0.847 1" mesh="RL_calf" />
                        <geom size="0.01 0.01 0.1" pos="0 0 -0.1" type="box" rgba="0 0 0 0" />
                        
                        <body name="RL_foot" pos="0 0 -0.226044482410381">
                            <inertial pos="0.00000000 0.00000000 0.00000000" mass="0.03900000" fullinertia="0.00000624 0.00000624 0.00000624 0.00000000 0.00000000 0.00000000" />
                            <geom type="mesh" contype="0" conaffinity="0" group="1" rgba="0.298 0.298 0.298 1" mesh="RL_foot" />
                            <geom size="0.02" type="sphere" rgba="0 0 0 1" />
                        </body>
                    </body>
                </body>
            </body>

            <body name="RR_hip" pos="-0.150422440000001 -0.0619648146458117 0.00287929128020871">
                <inertial pos="-0.06924676 -0.00308032 0.00003847" mass="0.88715151" fullinertia="0.00069961 0.00185513 0.00156952 -0.00005408 -0.00000026 -0.00000029" />
                <joint class="abduction" name="RR_hip_joint" pos="0 0 0" axis="1 0 0" range="-0.8 0.8" />
                <geom type="mesh" contype="0" conaffinity="0" group="1" rgba="0.847 0.847 0.847 1" mesh="RR_hip" />
                <geom size="0.04 0.03" euler="1.5707963 0 0" type="cylinder" rgba="0.913 0.913 0.847 0" />

                <body name="RR_thigh" pos="-0.0889996956253639 -0.0289499875000004 0">
                    <inertial pos="-0.02978034 -0.05141831 -0.01902502" mass="1.45068546" fullinertia="0.00384080 0.00724711 0.00574630 -0.00104560 -0.00254723 -0.00067018" />
                    <joint class="thigh" name="RR_thigh_joint" pos="0 0 0" axis="0 1 0" range="-1.04 4.18" />
                    <geom type="mesh" contype="0" conaffinity="0" group="1" rgba="1 1 1 1" mesh="RR_thigh" />
                    <geom size="0.02 0.02 0.1" pos="0 -0.08 -0.1" type="box" rgba="0.913 0.913 0.847 0" />
                    
                    <body name="RR_calf" pos="0 -0.0752999999999974 -0.220000271728273">
                        <inertial pos="0.05424733 -0.00001831 -0.03966504" mass="0.23880158" fullinertia="0.00057532 0.00208188 0.00158173 -0.00000006 0.00085447 0.00000006" />
                        <joint class="calf" name="RR_calf_joint" pos="0 0 0" axis="0 1 0" range="-2.69 -0.91" />
                        <geom type="mesh" contype="0" conaffinity="0" group="1" rgba="0.847 0.847 0.847 1" mesh="RR_calf" />
                        <geom size="0.01 0.01 0.1" pos="0 0 -0.1" type="box" rgba="0 0 0 0" />
                        
                        <body name="RR_foot" pos="0 0 -0.226044482410382">
                            <inertial pos="0.00000000 0.00000000 0.00000000" mass="0.03900000" fullinertia="0.00000624 0.00000624 0.00000624 0.00000000 0.00000000 0.00000000" />
                            <geom type="mesh" contype="0" conaffinity="0" group="1" rgba="0.298 0.298 0.298 1" mesh="RR_foot" />
                            <geom size="0.02" type="sphere" rgba="0 0 0 1" />
                        </body>
                    </body>
                </body>
            </body>
        </body>
    </worldbody>

    <actuator>       
        <motor class="abduction" name="FL_hip" gear="1" joint="FL_hip_joint" />
        <motor class="thigh" name="FL_thigh" gear="1" joint="FL_thigh_joint" />
        <motor class="calf" name="FL_calf" joint="FL_calf_joint" />
        <motor class="abduction" name="FR_hip" gear="1" joint="FR_hip_joint" />
        <motor class="thigh" name="FR_thigh" gear="1" joint="FR_thigh_joint" />
        <motor class="calf" name="FR_calf" joint="FR_calf_joint" />
        <motor class="abduction" name="RL_hip" gear="1" joint="RL_hip_joint" />
        <motor class="thigh" name="RL_thigh" gear="1" joint="RL_thigh_joint" />
        <motor class="calf" name="RL_calf" joint="RL_calf_joint" />
        <motor class="abduction" name="RR_hip" gear="1" joint="RR_hip_joint" />
        <motor class="thigh" name="RR_thigh" gear="1" joint="RR_thigh_joint" />
        <motor class="calf" name="RR_calf" joint="RR_calf_joint" />
    </actuator>

    <sensor>
        <jointpos name="FL_hip_pos" joint="FL_hip_joint" />
        <jointpos name="FL_thigh_pos" joint="FL_thigh_joint" />
        <jointpos name="FL_calf_pos" joint="FL_calf_joint" />
        <jointpos name="FR_hip_pos" joint="FR_hip_joint" />
        <jointpos name="FR_thigh_pos" joint="FR_thigh_joint" />
        <jointpos name="FR_calf_pos" joint="FR_calf_joint" />
        <jointpos name="RL_hip_pos" joint="RL_hip_joint" />
        <jointpos name="RL_thigh_pos" joint="RL_thigh_joint" />
        <jointpos name="RL_calf_pos" joint="RL_calf_joint" />
        <jointpos name="RR_hip_pos" joint="RR_hip_joint" />
        <jointpos name="RR_thigh_pos" joint="RR_thigh_joint" />
        <jointpos name="RR_calf_pos" joint="RR_calf_joint" />

        <jointvel name="FL_hip_vel" joint="FL_hip_joint" />
        <jointvel name="FL_thigh_vel" joint="FL_thigh_joint" />
        <jointvel name="FL_calf_vel" joint="FL_calf_joint" />
        <jointvel name="FR_hip_vel" joint="FR_hip_joint" />
        <jointvel name="FR_thigh_vel" joint="FR_thigh_joint" />
        <jointvel name="FR_calf_vel" joint="FR_calf_joint" />
        <jointvel name="RL_hip_vel" joint="RL_hip_joint" />
        <jointvel name="RL_thigh_vel" joint="RL_thigh_joint" />
        <jointvel name="RL_calf_vel" joint="RL_calf_joint" />
        <jointvel name="RR_hip_vel" joint="RR_hip_joint" />
        <jointvel name="RR_thigh_vel" joint="RR_thigh_joint" />
        <jointvel name="RR_calf_vel" joint="RR_calf_joint" />

        <accelerometer name="Body_Acc" site="imu" />
        <gyro name="Body_Gyro" site="imu" />
        <framepos name="Body_Pos" objtype="site" objname="imu" />
        <framequat name="Body_Quat" objtype="site" objname="imu" />
    </sensor>
</mujoco>